Workbook
Name UPDATE: 'Data Sheet'!$E$1

Sheet Instructions
A1: This excel sheet is for sole use of the buyer from drvijaymalik.com. Any copying and sharing of this excel sheet is prohibited.
A3: Instructions to the buyer:
A4: 1 | B4: This purchase is limited to the current version of the excel sheet only. Any future updates/versions of the excel sheet need to be bought separately. If in future, because of any reasons, screener changes the format of data it provides in the "Data Sheet" or makes this template invalid, then I would not be able to provide resolution of the issues in this excel template. In such a scenario, I might come up with a new version of the excel template. However, the new version needs to be bought separately by the users.
A5: 2 | B5: Detailed interpretations and descriptions of each of the parameters used for analysis on "Dr. Vijay Malik Analysis" sheet are provided as comment on the "narration" cell. To know more about any ratio, hover the mouse on the narration cell and the comment box will pop-up that contains the details about the parameter.
A6: 3 | B6: Please do not make any change to any formula/sheet in this excel workbook. Any change might lead to corruption of the formula links and might lead to erroneous results
A8: Steps to use this excel sheet:
B9: It is highly advised that investors read the following article to see step by step screenshots of using this excel template including uploading it on Screener website here:
B10: https://www.drvijaymalik.com/how-to-use-screener-in-export-to-excel-feature-tool/
A11: 1 | B11: Download and save the "Dr. Vijay Malik Screener Excel Template" file on your computer
A12: 2 | B12: log in to screener.in website with your user name and password
A13: 3 | B13: After logging in screener.in, copy and paste the following link in the web-browser and upload this excel sheet on this page.
B14: https://www.screener.in/excel/
B15: To upload, once you have reached the above webpage, click on the button "Choose File". A new dialogue box window will open. In the new window, navigate to the folder where you have saved the "Dr. Vijay Malik Screener Excel Template". Select the file and click open in the dialogue box. After clicking "Open" the dialogue box will close and you would see the abridged path of the selected file next to the button "Choose File". Now, click on the button "Upload" to finally upload the excel template in the screener system.
A16: 4 | B16: Done!
A17: 5 | B17: Now onwards, whenever you would click on export to excel button on the company page at screener website, you would get the data in this excel sheet format and you can analyse the stocks within a few minutes by analysing the data on the "Dr. Vijay Malik Analysis" sheet.
A19: Solutions to common errors:
A20: Error 1 | B20: "Dr Vijay Malik Analysis" worksheet is blank whereas the Data sheet is filled properly. Also, under the top menu bar, the following message might be present: PROTECTED VIEW: Be careful-files from the Internet can contain viruses. Unless you need to edit, it's safer to stay in Protected View. "Enable Editing"
B21: In Excel go to File > Options > Trust Center > Trust Center Settings > Protected View, and then uncheck Enabled Protected View for files originating from the Internet. Otherwise, when you would download "Export to Excel" file of companies from screener.in, the Data sheet would be filled properly but "Dr Vijay Malik Analysis" worksheet would remain blank.
A22: Error 2 | B22: When opening the Excel file, it shows an error: "We found a problem with some content. Do you want us to recover as much as we can. If you trust the source of this workbook, click yes"
B23: This error is due to unavailability/disabling of Visual Basic For Applications (VBA) while installing Microsoft Office. You may test this VBA error by accessing the Screener website on any different device like a mobile phone and then use the Export to Excel feature. On mobile phone, you may use either Google Sheets or Microsoft Excel for mobile phone to open the Excel template. You would notice that this error does not appear on mobile phone. On the laptop, installing the Visual Basics for Applications in the Microsoft Office by taking the following steps resolves this error. To do so, follow these steps: - Navigate to Control Panel > Programs and select Microsoft Office. - Click ‘Change’ and then select ‘Add or Remove Programs’. - Next, click the 'plus' sign provided next to Office Shared Features. - Click ‘Visual Basic for Applications’. After that, choose ‘Run from My Computer’ and hit the ‘Continue’ button. - Reboot your system when this process finishes. It would resolve the error.
A25: Target Company:
B26: The aim of the analysis is to find a debt free company, which is growing at a reasonable pace with sustained/improving profitability margins, which has been showing improvement in operating efficiency and has been generating positive Free Cash Flow over the years. If an investor is able to find such a company that is available at a cheap price, then investment in such a company has a high probability of creating wealth for the shareholders.

Sheet Dr Vijay Malik Analysis
A1: (₹ Crores/10 Millions) | D1: =+'Data Sheet'!B1 -> HESTER BIOSCIENCES LTD | L1: =+'Data Sheet'!K41 -> 0 | M1: << Latest available quarterly results
A2: Narration | B2: =+'Data Sheet'!B16 -> 0 | C2: =+'Data Sheet'!C16 -> 0 | D2: =+'Data Sheet'!D16 -> 0 | E2: =+'Data Sheet'!E16 -> 0 | F2: =+'Data Sheet'!F16 -> 0 | G2: =+'Data Sheet'!G16 -> 0 | H2: =+'Data Sheet'!H16 -> 0 | I2: =+'Data Sheet'!I16 -> 0 | ... K2: =+'Data Sheet'!K16 -> 0 | L2: Last 4 Quarters | M2: Total 10 Yr | N2: TRENDS: | O2: 10Yr | P2: 7Yr | Q2: 5Yr | R2: 3Yr | S2: TTM
A3: Sales | B3: =+'Data Sheet'!B17 -> 0 | C3: =+'Data Sheet'!C17 -> 0 | D3: =+'Data Sheet'!D17 -> 0 | E3: =+'Data Sheet'!E17 -> 0 | F3: =+'Data Sheet'!F17 -> 0 | G3: =+'Data Sheet'!G17 -> 0 | H3: =+'Data Sheet'!H17 -> 0 | I3: =+'Data Sheet'!I17 -> 0 | ... K3: =+'Data Sheet'!K17 -> 0 | L3: =IF(N68=TRUE,"",SUM('Data Sheet'!H42:K42)) | N3: Sales Grth | O3: =IF(B3=0,"",POWER($K3/B3,1/9)-1) | P3: =IF(D3=0,"",POWER($K3/D3,1/7)-1) | Q3: =IF(F3=0,"",POWER($K3/F3,1/5)-1) | R3: =IF(H3=0,"",POWER($K3/H3, 1/3)-1) | S3: =IF(N68=TRUE,"",L3/K3-1)
A4: Operating Profit | B4: =+'Data Sheet'!B17-'Data Sheet'!B18+'Data Sheet'!B19-SUM('Data Sheet'!B20:B24) -> 0 | C4: =+'Data Sheet'!C17-'Data Sheet'!C18+'Data Sheet'!C19-SUM('Data Sheet'!C20:C24) -> 0 | D4: =+'Data Sheet'!D17-'Data Sheet'!D18+'Data Sheet'!D19-SUM('Data Sheet'!D20:D24) -> 0 | E4: =+'Data Sheet'!E17-'Data Sheet'!E18+'Data Sheet'!E19-SUM('Data Sheet'!E20:E24) -> 0 | F4: =+'Data Sheet'!F17-'Data Sheet'!F18+'Data Sheet'!F19-SUM('Data Sheet'!F20:F24) -> 0 | G4: =+'Data Sheet'!G17-'Data Sheet'!G18+'Data Sheet'!G19-SUM('Data Sheet'!G20:G24) -> 0 | H4: =+'Data Sheet'!H17-'Data Sheet'!H18+'Data Sheet'!H19-SUM('Data Sheet'!H20:H24) -> 0 | I4: =+'Data Sheet'!I17-'Data Sheet'!I18+'Data Sheet'!I19-SUM('Data Sheet'!I20:I24) -> 0 | ... K4: =+'Data Sheet'!K17-'Data Sheet'!K18+'Data Sheet'!K19-SUM('Data Sheet'!K20:K24) -> 0 | L4: =+IF(N68=TRUE,"",SUM('Data Sheet'!H50:K50)) | N4: OPM | O4: =IF(SUM(B3:$K$3)=0,"",SUMPRODUCT(B5:$K$5,B3:$K$3)/SUM(B3:$K$3)) | P4: =IF(SUM(E3:$K$3)=0,"",SUMPRODUCT(E5:$K$5,E3:$K$3)/SUM(E3:$K$3)) | Q4: =IF(SUM(G3:$K$3)=0,"",SUMPRODUCT(G5:$K$5,G3:$K$3)/SUM(G3:$K$3)) | R4: =IF(SUM(I3:$K$3)=0, "", SUMPRODUCT(I5:$K$5,I3:$K$3)/SUM(I3:$K$3)) | S4: =IF(N68=TRUE,"",L5)
A5: Operating Profit Margin (OPM%) | B5: =IF(B4>0,B4/B3,0) -> 0 | C5: =IF(C4>0,C4/C3,0) -> 0 | D5: =IF(D4>0,D4/D3,0) -> 0 | E5: =IF(E4>0,E4/E3,0) -> 0 | F5: =IF(F4>0,F4/F3,0) -> 0 | G5: =IF(G4>0,G4/G3,0) -> 0 | H5: =IF(H4>0,H4/H3,0) -> 0 | I5: =IF(I4>0,I4/I3,0) -> 0 | ... K5: =IF(K4>0,K4/K3,0) -> 0 | L5: =+IF(N68=TRUE,"",IF(L4>0,L4/L3,0)) | N5: PAT Grth | O5: =IF(B13=0,"",POWER($K13/B13,1/9)-1) | P5: =IF(D13=0,"",POWER($K13/D13,1/7)-1) | Q5: =IF(F13=0,"",POWER($K13/F13,1/5)-1) | R5: =IF(H13=0,"",POWER($K13/H13, 1/3)-1) | S5: =+IF(N68=TRUE,"",L13/K13-1)
A6: Other Income | B6: =+'Data Sheet'!B25 -> 0 | C6: =+'Data Sheet'!C25 -> 0 | D6: =+'Data Sheet'!D25 -> 0 | E6: =+'Data Sheet'!E25 -> 0 | F6: =+'Data Sheet'!F25 -> 0 | G6: =+'Data Sheet'!G25 -> 0 | H6: =+'Data Sheet'!H25 -> 0 | I6: =+'Data Sheet'!I25 -> 0 | ... K6: =+'Data Sheet'!K25 -> 0 | L6: =IF(N68=TRUE,"",+SUM('Data Sheet'!H44:K44)) | M6: =SUM(B6:K6) -> 0 | N6: BV Grth | O6: =IF(B51=0,"",POWER($K51/B51,1/9)-1) | P6: =IF(D51=0,"",POWER($K51/D51,1/7)-1) | Q6: =IF(F51=0,"",POWER($K51/F51,1/5)-1) | R6: =IF(H51=0,"",POWER($K51/H51, 1/3)-1)
A7: EBITDA | B7: =+SUM(B4+B6) -> 0 | C7: =+SUM(C4+C6) -> 0 | D7: =+SUM(D4+D6) -> 0 | E7: =+SUM(E4+E6) -> 0 | F7: =+SUM(F4+F6) -> 0 | G7: =+SUM(G4+G6) -> 0 | H7: =+SUM(H4+H6) -> 0 | I7: =+SUM(I4+I6) -> 0 | ... K7: =+SUM(K4+K6) -> 0 | L7: =++IF(N68=TRUE,"",SUM(L4+L6)) | M7: =SUM(B7:K7) -> 0
A8: Interest | B8: =+'Data Sheet'!B27 -> 0 | C8: =+'Data Sheet'!C27 -> 0 | D8: =+'Data Sheet'!D27 -> 0 | E8: =+'Data Sheet'!E27 -> 0 | F8: =+'Data Sheet'!F27 -> 0 | G8: =+'Data Sheet'!G27 -> 0 | H8: =+'Data Sheet'!H27 -> 0 | I8: =+'Data Sheet'!I27 -> 0 | ... K8: =+'Data Sheet'!K27 -> 0 | L8: =+IF(N68=TRUE,"",SUM('Data Sheet'!H46:K46)) | M8: =SUM(B8:K8) -> 0 | N8: =+M54 -> 0 | O8: Interest Outgo
A9: Depreciation | B9: =+'Data Sheet'!B26 -> 0 | C9: =+'Data Sheet'!C26 -> 0 | D9: =+'Data Sheet'!D26 -> 0 | E9: =+'Data Sheet'!E26 -> 0 | F9: =+'Data Sheet'!F26 -> 0 | G9: =+'Data Sheet'!G26 -> 0 | H9: =+'Data Sheet'!H26 -> 0 | I9: =+'Data Sheet'!I26 -> 0 | ... K9: =+'Data Sheet'!K26 -> 0 | L9: =IF(N68=TRUE,"",+SUM('Data Sheet'!H45:K45)) | M9: =SUM(B9:K9) -> 0 | N9: PE History | O9: =+B46 -> #DIV/0! | P9: =+E46 -> #DIV/0! | Q9: =+G46 -> #DIV/0! | R9: =+I46 -> #DIV/0! | S9: =+O16/L13 -> #VALUE!
A10: Profit before tax (PBT) | B10: =+'Data Sheet'!B28 -> 0 | C10: =+'Data Sheet'!C28 -> 0 | D10: =+'Data Sheet'!D28 -> 0 | E10: =+'Data Sheet'!E28 -> 0 | F10: =+'Data Sheet'!F28 -> 0 | G10: =+'Data Sheet'!G28 -> 0 | H10: =+'Data Sheet'!H28 -> 0 | I10: =+'Data Sheet'!I28 -> 0 | ... K10: =+'Data Sheet'!K28 -> 0 | L10: =IF(N68=TRUE,"",+SUM('Data Sheet'!H47:K47)) | N10: CMP | O10: =+'Data Sheet'!B8 -> 0
A11: Tax | B11: =+'Data Sheet'!B29 -> 0 | C11: =+'Data Sheet'!C29 -> 0 | D11: =+'Data Sheet'!D29 -> 0 | E11: =+'Data Sheet'!E29 -> 0 | F11: =+'Data Sheet'!F29 -> 0 | G11: =+'Data Sheet'!G29 -> 0 | H11: =+'Data Sheet'!H29 -> 0 | I11: =+'Data Sheet'!I29 -> 0 | ... K11: =+'Data Sheet'!K29 -> 0 | L11: =IF(N68=TRUE,"",+SUM('Data Sheet'!H48:K48))
A12: Tax% | B12: =B11/B10 -> #DIV/0! | C12: =C11/C10 -> #DIV/0! | D12: =D11/D10 -> #DIV/0! | E12: =E11/E10 -> #DIV/0! | F12: =F11/F10 -> #DIV/0! | G12: =G11/G10 -> #DIV/0! | H12: =H11/H10 -> #DIV/0! | I12: =I11/I10 -> #DIV/0! | ... K12: =K11/K10 -> #DIV/0! | L12: =+IF(N68=TRUE,"",L11/L10) | N12: P/E | O12: =IF(N68=TRUE,O16/K13,O16/L13) -> #DIV/0!
A13: Net profit after tax (PAT) | B13: =+'Data Sheet'!B30 -> 0 | C13: =+'Data Sheet'!C30 -> 0 | D13: =+'Data Sheet'!D30 -> 0 | E13: =+'Data Sheet'!E30 -> 0 | F13: =+'Data Sheet'!F30 -> 0 | G13: =+'Data Sheet'!G30 -> 0 | H13: =+'Data Sheet'!H30 -> 0 | I13: =+'Data Sheet'!I30 -> 0 | ... K13: =+'Data Sheet'!K30 -> 0 | L13: =IF(N68=TRUE,"",+SUM('Data Sheet'!H49:K49)) | M13: =SUM(B13:K13) -> 0 | N13: P/B | O13: =+'Data Sheet'!B9/SUM('Data Sheet'!K57:K58) -> #DIV/0!
A14: Net Profit Margin (NPM%) | B14: =B13/B3 -> #DIV/0! | C14: =C13/C3 -> #DIV/0! | D14: =D13/D3 -> #DIV/0! | E14: =E13/E3 -> #DIV/0! | F14: =F13/F3 -> #DIV/0! | G14: =G13/G3 -> #DIV/0! | H14: =H13/H3 -> #DIV/0! | I14: =I13/I3 -> #DIV/0! | ... K14: =K13/K3 -> #DIV/0! | L14: =+IF(N68=TRUE,"",L13/L3) | N14: P/E*P/B | O14: =O12*O13 -> #DIV/0!
A15: Cash from Operating Activity (CFO) | B15: =+'Data Sheet'!B82 -> 0 | C15: =+'Data Sheet'!C82 -> 0 | D15: =+'Data Sheet'!D82 -> 0 | E15: =+'Data Sheet'!E82 -> 0 | F15: =+'Data Sheet'!F82 -> 0 | G15: =+'Data Sheet'!G82 -> 0 | H15: =+'Data Sheet'!H82 -> 0 | I15: =+'Data Sheet'!I82 -> 0 | ... K15: =+'Data Sheet'!K82 -> 0 | L15: CFO | M15: =SUM(B15:K15) -> 0 | N15: Div Yield | O15: ='Data Sheet'!K31/'Data Sheet'!B9 -> #DIV/0!
A16: Capex {(NFA+WIP) change+Dep} | C16: =+'Data Sheet'!C62+'Data Sheet'!C63-'Data Sheet'!B62-'Data Sheet'!B63+'Data Sheet'!C26 -> 0 | D16: =+'Data Sheet'!D62+'Data Sheet'!D63-'Data Sheet'!C62-'Data Sheet'!C63+'Data Sheet'!D26 -> 0 | E16: =+'Data Sheet'!E62+'Data Sheet'!E63-'Data Sheet'!D62-'Data Sheet'!D63+'Data Sheet'!E26 -> 0 | F16: =+'Data Sheet'!F62+'Data Sheet'!F63-'Data Sheet'!E62-'Data Sheet'!E63+'Data Sheet'!F26 -> 0 | G16: =+'Data Sheet'!G62+'Data Sheet'!G63-'Data Sheet'!F62-'Data Sheet'!F63+'Data Sheet'!G26 -> 0 | H16: =+'Data Sheet'!H62+'Data Sheet'!H63-'Data Sheet'!G62-'Data Sheet'!G63+'Data Sheet'!H26 -> 0 | I16: =+'Data Sheet'!I62+'Data Sheet'!I63-'Data Sheet'!H62-'Data Sheet'!H63+'Data Sheet'!I26 -> 0 | J16: =+'Data Sheet'!J62+'Data Sheet'!J63-'Data Sheet'!I62-'Data Sheet'!I63+'Data Sheet'!J26 -> 0 | K16: =+'Data Sheet'!K62+'Data Sheet'!K63-'Data Sheet'!J62-'Data Sheet'!J63+'Data Sheet'!K26 -> 0 | L16: Capex | M16: =SUM(B16:K16) -> 0 | N16: M. Cap | O16: =+'Data Sheet'!B9 -> 0
A17: FCF | C17: =+C15-C16 -> 0 | D17: =+D15-D16 -> 0 | E17: =+E15-E16 -> 0 | F17: =+F15-F16 -> 0 | G17: =+G15-G16 -> 0 | H17: =+H15-H16 -> 0 | I17: =+I15-I16 -> 0 | J17: =+J15-J16 -> 0 | K17: =+K15-K16 -> 0 | L17: FCF | M17: =+M15-M16 -> 0 | N17: =SUM(B45:K45) -> 0 | O17: Total Retained Earnings (RE) in 10 Yrs (A)
A18: Total Debt (D) | B18: =+'Data Sheet'!B59 -> 0 | C18: =+'Data Sheet'!C59 -> 0 | D18: =+'Data Sheet'!D59 -> 0 | E18: =+'Data Sheet'!E59 -> 0 | F18: =+'Data Sheet'!F59 -> 0 | G18: =+'Data Sheet'!G59 -> 0 | H18: =+'Data Sheet'!H59 -> 0 | I18: =+'Data Sheet'!I59 -> 0 | ... K18: =+'Data Sheet'!K59 -> 0 | L18: FCFE.1 (FCF-Int exp) | M18: =+M17-M8 -> 0 | N18: =L47-IF(N22>0,N22*'Data Sheet'!B6,B47) -> 0 | O18: Total increase in Mcap in 10 yrs (B)
A19: Share Capital | B19: =+'Data Sheet'!B57 -> 0 | C19: =+'Data Sheet'!C57 -> 0 | D19: =+'Data Sheet'!D57 -> 0 | E19: =+'Data Sheet'!E57 -> 0 | F19: =+'Data Sheet'!F57 -> 0 | G19: =+'Data Sheet'!G57 -> 0 | H19: =+'Data Sheet'!H57 -> 0 | I19: =+'Data Sheet'!I57 -> 0 | ... K19: =+'Data Sheet'!K57 -> 0 | L19: FCFE.2 (FCFE.1 + OI) | M19: =M18+M6 -> 0 | N19: =N18/N17 -> #DIV/0! | O19: Value created per INR of RE (B/A)
A20: Dividend Paid (Div) Without DDT | B20: =+'Data Sheet'!B31 -> 0 | C20: =+'Data Sheet'!C31 -> 0 | D20: =+'Data Sheet'!D31 -> 0 | E20: =+'Data Sheet'!E31 -> 0 | F20: =+'Data Sheet'!F31 -> 0 | G20: =+'Data Sheet'!G31 -> 0 | H20: =+'Data Sheet'!H31 -> 0 | I20: =+'Data Sheet'!I31 -> 0 | ... K20: =+'Data Sheet'!K31 -> 0 | L20: Total Div 10 Yrs | M20: =SUM(B43:K43) -> 0 | N20: =+(L47/B47)^(1/((TODAY()-B2)/365))-1 -> #DIV/0! | O20: Mcap CAGR 10Y
A21: Net Cash Generation (FCF+OI+Debt-Int-Div) | C21: =+C17+C6+(C18-B18)-C20-C8 -> 0 | D21: =+D17+D6+(D18-C18)-D20-D8 -> 0 | E21: =+E17+E6+(E18-D18)-E20-E8 -> 0 | F21: =+F17+F6+(F18-E18)-F20-F8 -> 0 | G21: =+G17+G6+(G18-F18)-G20-G8 -> 0 | H21: =+H17+H6+(H18-G18)-H20-H8 -> 0 | I21: =+I17+I6+(I18-H18)-I20-I8 -> 0 | J21: =+J17+J6+(J18-I18)-J20-J8 -> 0 | K21: =+K17+K6+(K18-J18)-K20-K8 -> 0 | L21: Inc. in Debt 10Y | M21: =+K18-B18 -> 0
A22: Cash + Investments (CI +NCI) | B22: =+'Data Sheet'!B64+'Data Sheet'!B69 -> 0 | C22: =+'Data Sheet'!C64+'Data Sheet'!C69 -> 0 | D22: =+'Data Sheet'!D64+'Data Sheet'!D69 -> 0 | E22: =+'Data Sheet'!E64+'Data Sheet'!E69 -> 0 | F22: =+'Data Sheet'!F64+'Data Sheet'!F69 -> 0 | G22: =+'Data Sheet'!G64+'Data Sheet'!G69 -> 0 | H22: =+'Data Sheet'!H64+'Data Sheet'!H69 -> 0 | I22: =+'Data Sheet'!I64+'Data Sheet'!I69 -> 0 | ... K22: =+'Data Sheet'!K64+'Data Sheet'!K69 -> 0 | L22: Surplus funds | M22: =+M19-M20+M21 -> 0 | N22: 0 | O22: Closing share price on March 31, 10 years back
A24: Self-Sustainable Growth Rate (SSGR) | E24: =AVERAGE(C34:E34)*AVERAGE(C14:E14)*(1-AVERAGE(C44:E44))-AVERAGE(C68:E68) -> #DIV/0! | F24: =AVERAGE(D34:F34)*AVERAGE(D14:F14)*(1-AVERAGE(D44:F44))-AVERAGE(D68:F68) -> #DIV/0! | G24: =AVERAGE(E34:G34)*AVERAGE(E14:G14)*(1-AVERAGE(E44:G44))-AVERAGE(E68:G68) -> #DIV/0! | H24: =AVERAGE(F34:H34)*AVERAGE(F14:H14)*(1-AVERAGE(F44:H44))-AVERAGE(F68:H68) -> #DIV/0! | I24: =AVERAGE(G34:I34)*AVERAGE(G14:I14)*(1-AVERAGE(G44:I44))-AVERAGE(G68:I68) -> #DIV/0! | J24: =AVERAGE(H34:J34)*AVERAGE(H14:J14)*(1-AVERAGE(H44:J44))-AVERAGE(H68:J68) -> #DIV/0! | K24: =AVERAGE(I34:K34)*AVERAGE(I14:K14)*(1-AVERAGE(I44:K44))-AVERAGE(I68:K68) -> #DIV/0! | L24: FCF/CFO | M24: =+M17/M15 -> #DIV/0!
L25: Change in 10 Yrs
A26: Trade Receivables | B26: =+'Data Sheet'!B67 -> 0 | C26: =+'Data Sheet'!C67 -> 0 | D26: =+'Data Sheet'!D67 -> 0 | E26: =+'Data Sheet'!E67 -> 0 | F26: =+'Data Sheet'!F67 -> 0 | G26: =+'Data Sheet'!G67 -> 0 | H26: =+'Data Sheet'!H67 -> 0 | I26: =+'Data Sheet'!I67 -> 0 | ... K26: =+'Data Sheet'!K67 -> 0 | L26: =+B26-K26 -> 0
A27: Inventory | B27: =+'Data Sheet'!B68 -> 0 | C27: =+'Data Sheet'!C68 -> 0 | D27: =+'Data Sheet'!D68 -> 0 | E27: =+'Data Sheet'!E68 -> 0 | F27: =+'Data Sheet'!F68 -> 0 | G27: =+'Data Sheet'!G68 -> 0 | H27: =+'Data Sheet'!H68 -> 0 | I27: =+'Data Sheet'!I68 -> 0 | ... K27: =+'Data Sheet'!K68 -> 0 | L27: =+B27-K27 -> 0
A29: PBT/Avg. NFA (<10%,>25%) | C29: =C10/(AVERAGE(B40:C40)) -> #DIV/0! | D29: =D10/(AVERAGE(C40:D40)) -> #DIV/0! | E29: =E10/(AVERAGE(D40:E40)) -> #DIV/0! | F29: =F10/(AVERAGE(E40:F40)) -> #DIV/0! | G29: =G10/(AVERAGE(F40:G40)) -> #DIV/0! | H29: =H10/(AVERAGE(G40:H40)) -> #DIV/0! | I29: =I10/(AVERAGE(H40:I40)) -> #DIV/0! | J29: =J10/(AVERAGE(I40:J40)) -> #DIV/0! | K29: =K10/(AVERAGE(J40:K40)) -> #DIV/0!
A30: ROE on Avg Equity (<7%,>25%) | C30: =C13/AVERAGE(B51:C51) -> #DIV/0! | D30: =D13/AVERAGE(C51:D51) -> #DIV/0! | E30: =E13/AVERAGE(D51:E51) -> #DIV/0! | F30: =F13/AVERAGE(E51:F51) -> #DIV/0! | G30: =G13/AVERAGE(F51:G51) -> #DIV/0! | H30: =H13/AVERAGE(G51:H51) -> #DIV/0! | I30: =I13/AVERAGE(H51:I51) -> #DIV/0! | J30: =J13/AVERAGE(I51:J51) -> #DIV/0! | K30: =K13/AVERAGE(J51:K51) -> #DIV/0!
A31: ROCE (EBIT on Avg CE/TA) (<10%,>35%) | C31: =(C10+C8)/AVERAGE('Data Sheet'!B61:C61) -> #DIV/0! | D31: =(D10+D8)/AVERAGE('Data Sheet'!C61:D61) -> #DIV/0! | E31: =(E10+E8)/AVERAGE('Data Sheet'!D61:E61) -> #DIV/0! | F31: =(F10+F8)/AVERAGE('Data Sheet'!E61:F61) -> #DIV/0! | G31: =(G10+G8)/AVERAGE('Data Sheet'!F61:G61) -> #DIV/0! | H31: =(H10+H8)/AVERAGE('Data Sheet'!G61:H61) -> #DIV/0! | I31: =(I10+I8)/AVERAGE('Data Sheet'!H61:I61) -> #DIV/0! | J31: =(J10+J8)/AVERAGE('Data Sheet'!I61:J61) -> #DIV/0! | K31: =(K10+K8)/AVERAGE('Data Sheet'!J61:K61) -> #DIV/0!
A32: Incremental ROE 3Yr Rolling | E32: =+(E13-B13)/SUM(B45:D45) -> #DIV/0! | F32: =+(F13-C13)/SUM(C45:E45) -> #DIV/0! | G32: =+(G13-D13)/SUM(D45:F45) -> #DIV/0! | H32: =+(H13-E13)/SUM(E45:G45) -> #DIV/0! | I32: =+(I13-F13)/SUM(F45:H45) -> #DIV/0! | J32: =+(J13-G13)/SUM(G45:I45) -> #DIV/0! | K32: =+(K13-H13)/SUM(H45:J45) -> #DIV/0!
A34: Net Fixed Asset Turnover (High is better) | C34: =+'Data Sheet'!C17/(('Data Sheet'!B62+'Data Sheet'!C62)/2) -> #DIV/0! | D34: =+'Data Sheet'!D17/(('Data Sheet'!C62+'Data Sheet'!D62)/2) -> #DIV/0! | E34: =+'Data Sheet'!E17/(('Data Sheet'!D62+'Data Sheet'!E62)/2) -> #DIV/0! | F34: =+'Data Sheet'!F17/(('Data Sheet'!E62+'Data Sheet'!F62)/2) -> #DIV/0! | G34: =+'Data Sheet'!G17/(('Data Sheet'!F62+'Data Sheet'!G62)/2) -> #DIV/0! | H34: =+'Data Sheet'!H17/(('Data Sheet'!G62+'Data Sheet'!H62)/2) -> #DIV/0! | I34: =+'Data Sheet'!I17/(('Data Sheet'!H62+'Data Sheet'!I62)/2) -> #DIV/0! | J34: =+'Data Sheet'!J17/(('Data Sheet'!I62+'Data Sheet'!J62)/2) -> #DIV/0! | K34: =+'Data Sheet'!K17/(('Data Sheet'!J62+'Data Sheet'!K62)/2) -> #DIV/0!
A35: Receivables days (Low is better) | C35: =365/('Data Sheet'!C17/AVERAGE('Data Sheet'!B67:C67)) -> #DIV/0! | D35: =365/('Data Sheet'!D17/AVERAGE('Data Sheet'!C67:D67)) -> #DIV/0! | E35: =365/('Data Sheet'!E17/AVERAGE('Data Sheet'!D67:E67)) -> #DIV/0! | F35: =365/('Data Sheet'!F17/AVERAGE('Data Sheet'!E67:F67)) -> #DIV/0! | G35: =365/('Data Sheet'!G17/AVERAGE('Data Sheet'!F67:G67)) -> #DIV/0! | H35: =365/('Data Sheet'!H17/AVERAGE('Data Sheet'!G67:H67)) -> #DIV/0! | I35: =365/('Data Sheet'!I17/AVERAGE('Data Sheet'!H67:I67)) -> #DIV/0! | J35: =365/('Data Sheet'!J17/AVERAGE('Data Sheet'!I67:J67)) -> #DIV/0! | K35: =365/('Data Sheet'!K17/AVERAGE('Data Sheet'!J67:K67)) -> #DIV/0!
A36: Inventory Turnover (High is better) | C36: ='Data Sheet'!C17/(AVERAGE('Data Sheet'!B68:C68)) -> #DIV/0! | D36: ='Data Sheet'!D17/(AVERAGE('Data Sheet'!C68:D68)) -> #DIV/0! | E36: ='Data Sheet'!E17/(AVERAGE('Data Sheet'!D68:E68)) -> #DIV/0! | F36: ='Data Sheet'!F17/(AVERAGE('Data Sheet'!E68:F68)) -> #DIV/0! | G36: ='Data Sheet'!G17/(AVERAGE('Data Sheet'!F68:G68)) -> #DIV/0! | H36: ='Data Sheet'!H17/(AVERAGE('Data Sheet'!G68:H68)) -> #DIV/0! | I36: ='Data Sheet'!I17/(AVERAGE('Data Sheet'!H68:I68)) -> #DIV/0! | J36: ='Data Sheet'!J17/(AVERAGE('Data Sheet'!I68:J68)) -> #DIV/0! | K36: ='Data Sheet'!K17/(AVERAGE('Data Sheet'!J68:K68)) -> #DIV/0!
A37: Months of RM held as Inv. (Low is better) | C37: =(365/('Data Sheet'!C18/(AVERAGE('Data Sheet'!B68:C68))))/30 -> #DIV/0! | D37: =(365/('Data Sheet'!D18/(AVERAGE('Data Sheet'!C68:D68))))/30 -> #DIV/0! | E37: =(365/('Data Sheet'!E18/(AVERAGE('Data Sheet'!D68:E68))))/30 -> #DIV/0! | F37: =(365/('Data Sheet'!F18/(AVERAGE('Data Sheet'!E68:F68))))/30 -> #DIV/0! | G37: =(365/('Data Sheet'!G18/(AVERAGE('Data Sheet'!F68:G68))))/30 -> #DIV/0! | H37: =(365/('Data Sheet'!H18/(AVERAGE('Data Sheet'!G68:H68))))/30 -> #DIV/0! | I37: =(365/('Data Sheet'!I18/(AVERAGE('Data Sheet'!H68:I68))))/30 -> #DIV/0! | J37: =(365/('Data Sheet'!J18/(AVERAGE('Data Sheet'!I68:J68))))/30 -> #DIV/0! | K37: =(365/('Data Sheet'!K18/(AVERAGE('Data Sheet'!J68:K68))))/30 -> #DIV/0!
A38: Working capital cycle days (Rec + Inv Days) | C38: =+C35+365/C36 -> #DIV/0! | D38: =+D35+365/D36 -> #DIV/0! | E38: =+E35+365/E36 -> #DIV/0! | F38: =+F35+365/F36 -> #DIV/0! | G38: =+G35+365/G36 -> #DIV/0! | H38: =+H35+365/H36 -> #DIV/0! | I38: =+I35+365/I36 -> #DIV/0! | J38: =+J35+365/J36 -> #DIV/0! | K38: =+K35+365/K36 -> #DIV/0!
A40: Net Fixed Assets (NFA) | B40: =+'Data Sheet'!B62 -> 0 | C40: =+'Data Sheet'!C62 -> 0 | D40: =+'Data Sheet'!D62 -> 0 | E40: =+'Data Sheet'!E62 -> 0 | F40: =+'Data Sheet'!F62 -> 0 | G40: =+'Data Sheet'!G62 -> 0 | H40: =+'Data Sheet'!H62 -> 0 | I40: =+'Data Sheet'!I62 -> 0 | ... K40: =+'Data Sheet'!K62 -> 0
A41: Capital Work in Progress (CWIP) | B41: =+'Data Sheet'!B63 -> 0 | C41: =+'Data Sheet'!C63 -> 0 | D41: =+'Data Sheet'!D63 -> 0 | E41: =+'Data Sheet'!E63 -> 0 | F41: =+'Data Sheet'!F63 -> 0 | G41: =+'Data Sheet'!G63 -> 0 | H41: =+'Data Sheet'!H63 -> 0 | I41: =+'Data Sheet'!I63 -> 0 | ... K41: =+'Data Sheet'!K63 -> 0
A43: Dividend Paid (Div) Without DDT | B43: =+'Data Sheet'!B31 -> 0 | C43: =+'Data Sheet'!C31 -> 0 | D43: =+'Data Sheet'!D31 -> 0 | E43: =+'Data Sheet'!E31 -> 0 | F43: =+'Data Sheet'!F31 -> 0 | G43: =+'Data Sheet'!G31 -> 0 | H43: =+'Data Sheet'!H31 -> 0 | I43: =+'Data Sheet'!I31 -> 0 | ... K43: =+'Data Sheet'!K31 -> 0 | M43: =+SUM(B43:K43) -> 0 | N43: Div Grth | O43: =IF(B43=0,"",POWER($K43/B43,1/9)-1) | P43: =IF(D43=0,"",POWER($K43/D43,1/7)-1) | Q43: =IF(F43=0,"",POWER($K43/F43,1/5)-1) | R43: =IF(H43=0,"",POWER($K43/H43, 1/3)-1) | S43: =IF(ISERROR(MAX(IF(J43=0,"",(K43-J43)/J43),IF(K43=0,"",(#REF!-K43)/K43))),"",MAX(IF(J43=0,"",(K43-J43)/J43),IF(K43=0,"",(#REF!-K43)/K43)))
A44: Dividend Payout (Div/PAT) | B44: =+'Data Sheet'!B31/'Data Sheet'!B30 -> #DIV/0! | C44: =+'Data Sheet'!C31/'Data Sheet'!C30 -> #DIV/0! | D44: =+'Data Sheet'!D31/'Data Sheet'!D30 -> #DIV/0! | E44: =+'Data Sheet'!E31/'Data Sheet'!E30 -> #DIV/0! | F44: =+'Data Sheet'!F31/'Data Sheet'!F30 -> #DIV/0! | G44: =+'Data Sheet'!G31/'Data Sheet'!G30 -> #DIV/0! | H44: =+'Data Sheet'!H31/'Data Sheet'!H30 -> #DIV/0! | I44: =+'Data Sheet'!I31/'Data Sheet'!I30 -> #DIV/0! | ... K44: =+'Data Sheet'!K31/'Data Sheet'!K30 -> #DIV/0!
A45: Retained Earnings (RE=PAT-Div) | B45: =+'Data Sheet'!B30-'Data Sheet'!B31 -> 0 | C45: =+'Data Sheet'!C30-'Data Sheet'!C31 -> 0 | D45: =+'Data Sheet'!D30-'Data Sheet'!D31 -> 0 | E45: =+'Data Sheet'!E30-'Data Sheet'!E31 -> 0 | F45: =+'Data Sheet'!F30-'Data Sheet'!F31 -> 0 | G45: =+'Data Sheet'!G30-'Data Sheet'!G31 -> 0 | H45: =+'Data Sheet'!H30-'Data Sheet'!H31 -> 0 | I45: =+'Data Sheet'!I30-'Data Sheet'!I31 -> 0 | ... K45: =+'Data Sheet'!K30-'Data Sheet'!K31 -> 0
...

Sheet Version History
A1: Version No | B1: Changes
A2: 3.2 | B2: Updated the Instructions sheet and added solution to the error "We found a problem with some content. Do you want us to recover as much as we can. If you trust the source of this workbook, click yes"
A3: 3.1 | B3: Updated the formula for TTM average PE in Cell "S46" to link from "O13" to "O12"
A4: 3 | B4: 1) Added new parameter: Net Cash Generation 2) Updated FCFE calculation at 2 levels: 2.a) FCFE.1 (FCF-Int exp) and 2.b) FCFE.2 (FCFE.1 + OI) 3) Added new parameter: Surplus Funds: FCFE.2 - Dividend Payouts + Increase in debt in 10 years 4) Added new parameter: No. of Months of raw material held as inventory 5) Added new parameter: CAGR of market cap from the data 10 year’s back to the latest date. 6) Added PE History in row number N10:S10 with PE 10Y back, 7Y back, 5Y back, 3Y back and TTM PE 7) Avg. PE data field shifted to Row 46 8) Shifted Interest outgo next to interest expense 9) Updated the description and interpretations of all the parameters of the Analysis Sheet as “comment” in the narration/label cell
A5: 2 | B5: Comprehensively revised the Excel Sheet: 1. Added the section of various expenses as a percentage of sales (Raw material, Power & Fuel, Employee Costs, Selling and Admin Costs, other manufacturing expenses and Other expenses as a percentage of sales). 2. Added working capital cycle (days) calculation based on inventory and trade receivables. 3. Added rows for trade receivables and inventory and the calculation of total funds consumed in/released from receivables and inventory over last 10 years. It is helpful in quick assessment of one of the key reasons for differences in PAT and CFO. 4. Brought together the data of CFO, Capex, FCF, Total Debt, Share Capital, Dividend Payment and Cash + investment on the upper section of dashboard. This is essential to analyse the cash movements in the company in any year. E.g. in case, the company had a negative FCF, then investor can immediately see the sources of funds to meet negative FCF. In such cases, the company may have raised more debt, which will increase total debt. OR the company may have raised additional equity, which will show as increase in share capital. OR the company may have used existing cash, which will show as decline in cash + investment. Similarly, if a company has positive FCF, then it may show as an increase in cash + investment OR as decline in total debt OR high dividend payments or buyback (decline in share capital). The presence of these data points at the top section of the dashboard helps in quick assessment of flow of cash in the company over the years. 5. Added a calcuation of Free Cash Flow to Equity (FCFE), which is calculated as (FCF-interest expense). FCFE calculated in this manner indicates the surplus cash out of CFO remaining after meeting capital expenditure (Capex) and all interest payments (both capitalzied as part of capex as well as the interest expensed in P&L) 6. Unhid the "depreciation" row in the dashboard 7. Removed the ratio "SG to Capex" as it was not proving to be useful.
A6: 1.6 | B6: Rectified the error which has creeped in while correcting the issues of version 1.5. The error was leading to the cells for the data of past market cap and P/E ratios in the analysis sheet were not getting filled. The issue has been rectified in Version 1.6
A7: 1.5 | B7: 1. Many times, in cases where the data for last 4 quarters is not present in screener.in (either the company does not declare quarterly results e.g. for consolidated financials OR due to any reasons the screener data sheet does not have quarterly data), then the P/E ratio cell (O14) in the excel sheet which used to calculate P/E based on last 12 months (TTM) figures, loses its accuracy. Therefore, now we have edited the formula in such a fashion that if the data of any of the last 4 quarters is not present, then the P/E ratio cell (O14) will give the P/E ratio based on last FY PAT instead of the TTM PAT. 2. In cases, where the data for any of the last 4 quarters is not present, then the entire TTM column (i.e. column L), will remain blank.
A8: 1.4 | B8: Unprotected the file with open access to users to edit & customize the template as per their preference
A9: 1.3 | B9: Resolved the reported error: "if there is no data for particular year in screener, the template has taken the default data ( ie data of Vinati Organics). e.g. when tried to analyse "Wonderla" , in screener there is no data for 2006, but after uploading the template & exporting the excel , it shows the data for 2006 of Vinati organics( default excel sheet)"
A10: 1.2 | B10: 1. Updated "Instructions" sheet with the guidelines to change Microsoft Excel settings to disable the "Protected View for files originating from the Internet". The change of this setting resolves the issue where upon downloading the "Export to Excel" file from screener.in, the "Data Sheet" was filled properly, however, "Dr. Vijay Malik Analysis" sheet remained blank.
A11: 1.1 | B11: 1. Added functionality to edit the cells "Closing share price on March 31, 10 years back" and "Cost of funds" in the sheet "Dr. Vijay Malik Analysis" to allow users to enter desired values. 2. Added interpretation and description of parameters "FCF/CFO" and "SG to Capex" in the "Description" Sheet. 3. Updated description of "Share Capital" to add the conditional formatting details in the "Description" Sheet. 4. Added sheet "Version History".

Sheet Data Sheet
A1: COMPANY NAME | B1: HESTER BIOSCIENCES LTD | E1: =IF(B2<>B3, "A NEW VERSION OF THE WORKSHEET IS AVAILABLE", "")
A2: LATEST VERSION | B2: 2.1 | E2: PLEASE DO NOT MAKE ANY CHANGES TO THIS SHEET
A3: CURRENT VERSION | B3: 2.1
A5: META
A6: Number of shares | B6: =IF(B9>0, B9/B8, 0) -> 0
A7: Face Value
A8: Current Price
A9: Market Capitalization
A15: PROFIT & LOSS
A16: Report Date
A17: Sales
A18: Raw Material Cost
A19: Change in Inventory
A20: Power and Fuel
A21: Other Mfr. Exp
A22: Employee Cost
A23: Selling and admin
... A92: DERIVED:
A93: Adjusted Equity Shares in Cr | B93: =IF($B7>0,(B70*B72/$B7)+SUM(C71:$K71),0)/10000000 -> 0 | C93: =IF($B7>0,(C70*C72/$B7)+SUM(D71:$K71),0)/10000000 -> 0 | D93: =IF($B7>0,(D70*D72/$B7)+SUM(E71:$K71),0)/10000000 -> 0 | E93: =IF($B7>0,(E70*E72/$B7)+SUM(F71:$K71),0)/10000000 -> 0 | F93: =IF($B7>0,(F70*F72/$B7)+SUM(G71:$K71),0)/10000000 -> 0 | G93: =IF($B7>0,(G70*G72/$B7)+SUM(H71:$K71),0)/10000000 -> 0 | H93: =IF($B7>0,(H70*H72/$B7)+SUM(I71:$K71),0)/10000000 -> 0 | I93: =IF($B7>0,(I70*I72/$B7)+SUM(J71:$K71),0)/10000000 -> 0 | J93: =IF($B7>0,(J70*J72/$B7)+SUM(K71:$K71),0)/10000000 -> 0 | K93: =IF($B7>0,(K70*K72/$B7),0)/10000000 -> 0
